08.03.20   13:55:18 - moduls - ERROR - ERROR on logging form
Traceback (most recent call last):
  File "C:\Users\ART\5\instagram_bot\py_raw\moduls.py", line 67, in logging_in
    browser.get(link_for_login)
  File "C:\Users\ART\AppData\Local\Programs\Python\Python38\lib\site-packages\selenium\webdriver\remote\webdriver.py", line 333, in get
    self.execute(Command.GET, {'url': url})
  File "C:\Users\ART\AppData\Local\Programs\Python\Python38\lib\site-packages\selenium\webdriver\remote\webdriver.py", line 321, in execute
    self.error_handler.check_response(response)
  File "C:\Users\ART\AppData\Local\Programs\Python\Python38\lib\site-packages\selenium\webdriver\remote\errorhandler.py", line 242, in check_response
    raise exception_class(message, screen, stacktrace)
selenium.common.exceptions.WebDriverException: Message: unknown error: cannot determine loading status
from disconnected: received Inspector.detached event
  (Session info: chrome=80.0.3987.132)

